import type { MatchersContract } from "../../helpers/contracts.js";
import type { HardhatEthers } from "@nomicfoundation/hardhat-ethers/types";
import type { EthereumProvider } from "hardhat/types/providers";

import path from "node:path";
import { before, beforeEach, describe, it } from "node:test";
import util from "node:util";

import { HardhatError } from "@nomicfoundation/hardhat-errors";
import {
  assertRejectsWithHardhatError,
  assertThrowsHardhatError,
  useEphemeralFixtureProject,
} from "@nomicfoundation/hardhat-test-utils";
import { AssertionError, expect } from "chai";

import { addChaiMatchers } from "../../../src/internal/add-chai-matchers.js";
import {
  runSuccessfulAsserts,
  runFailedAsserts,
  mineSuccessfulTransaction,
  mineRevertedTransaction,
  initEnvironment,
} from "../../helpers/helpers.js";

addChaiMatchers();

describe("INTEGRATION: Revert", { timeout: 60000 }, () => {
  describe("with the in-process hardhat network", () => {
    useEphemeralFixtureProject("hardhat-project");
    runTests();
  });

  function runTests() {
    // deploy Matchers contract before each test
    let matchers: MatchersContract;

    let provider: EthereumProvider;
    let ethers: HardhatEthers;

    before(async () => {
      ({ ethers, provider } = await initEnvironment("reverted"));
    });

    beforeEach(async () => {
      const Matchers = await ethers.getContractFactory<[], MatchersContract>(
        "Matchers",
      );
      matchers = await Matchers.deploy();
    });

    // helpers
    const expectAssertionError = async (x: Promise<void>, message: string) => {
      return expect(x).to.be.eventually.rejectedWith(AssertionError, message);
    };

    describe("with a string as its subject", () => {
      it("hash of a successful transaction", async () => {
        const { hash } = await mineSuccessfulTransaction(provider, ethers);

        await expectAssertionError(
          expect(hash).to.be.revert(ethers),
          "Expected transaction to be reverted",
        );
        await expect(hash).to.not.be.revert(ethers);
      });

      it("hash of a reverted transaction", async () => {
        const { hash } = await mineRevertedTransaction(
          provider,
          ethers,
          matchers,
        );

        await expect(hash).to.be.revert(ethers);
        await expectAssertionError(
          expect(hash).to.not.be.revert(ethers),
          "Expected transaction NOT to be reverted",
        );
      });

      it("invalid string", async () => {
        await assertRejectsWithHardhatError(
          () => expect("0x123").to.be.revert(ethers),
          HardhatError.ERRORS.CHAI_MATCHERS.GENERAL
            .EXPECTED_VALID_TRANSACTION_HASH,
          {
            hash: "0x123",
          },
        );

        await assertRejectsWithHardhatError(
          () => expect("0x123").to.not.be.revert(ethers),
          HardhatError.ERRORS.CHAI_MATCHERS.GENERAL
            .EXPECTED_VALID_TRANSACTION_HASH,
          {
            hash: "0x123",
          },
        );
      });

      it("promise of a hash of a successful transaction", async () => {
        const { hash } = await mineSuccessfulTransaction(provider, ethers);
        await expectAssertionError(
          expect(Promise.resolve(hash)).to.be.revert(ethers),
          "Expected transaction to be reverted",
        );
        await expect(Promise.resolve(hash)).to.not.be.revert(ethers);
      });

      it("promise of a hash of a reverted transaction", async () => {
        const { hash } = await mineRevertedTransaction(
          provider,
          ethers,
          matchers,
        );
        await expect(Promise.resolve(hash)).to.be.revert(ethers);
        await expectAssertionError(
          expect(Promise.resolve(hash)).to.not.be.revert(ethers),
          "Expected transaction NOT to be reverted",
        );
      });

      it("promise of an invalid string", async () => {
        await assertRejectsWithHardhatError(
          () => expect(Promise.resolve("0x123")).to.be.revert(ethers),
          HardhatError.ERRORS.CHAI_MATCHERS.GENERAL
            .EXPECTED_VALID_TRANSACTION_HASH,
          {
            hash: "0x123",
          },
        );

        await assertRejectsWithHardhatError(
          () => expect(Promise.resolve("0x123")).to.not.be.revert(ethers),
          HardhatError.ERRORS.CHAI_MATCHERS.GENERAL
            .EXPECTED_VALID_TRANSACTION_HASH,
          {
            hash: "0x123",
          },
        );
      });

      it("promise of an byte32 string", async () => {
        await expect(
          Promise.resolve(
            "0x3230323400000000000000000000000000000000000000000000000000000000",
          ),
        ).not.to.be.revert(ethers);
      });
    });

    describe("with a TxResponse as its subject", () => {
      it("TxResponse of a successful transaction", async () => {
        const tx = await mineSuccessfulTransaction(provider, ethers);

        await expectAssertionError(
          expect(tx).to.be.revert(ethers),
          "Expected transaction to be reverted",
        );
        await expect(tx).to.not.be.revert(ethers);
      });

      it("TxResponse of a reverted transaction", async () => {
        const tx = await mineRevertedTransaction(provider, ethers, matchers);

        await expect(tx).to.be.revert(ethers);
        await expectAssertionError(
          expect(tx).to.not.be.revert(ethers),
          "Expected transaction NOT to be reverted",
        );
      });

      it("promise of a TxResponse of a successful transaction", async () => {
        const txPromise = mineSuccessfulTransaction(provider, ethers);

        await expectAssertionError(
          expect(txPromise).to.be.revert(ethers),
          "Expected transaction to be reverted",
        );
        await expect(txPromise).to.not.be.revert(ethers);
      });

      it("promise of a TxResponse of a reverted transaction", async () => {
        const txPromise = mineRevertedTransaction(provider, ethers, matchers);

        await expect(txPromise).to.be.revert(ethers);
        await expectAssertionError(
          expect(txPromise).to.not.be.revert(ethers),
          "Expected transaction NOT to be reverted",
        );
      });

      it("reverted: should throw if chained to another non-chainable method", () => {
        assertThrowsHardhatError(
          () =>
            expect(matchers.revertsWith("bar"))
              .to.be.revertedWith("bar")
              .and.to.be.revert(ethers),
          HardhatError.ERRORS.CHAI_MATCHERS.GENERAL
            .MATCHER_CANNOT_BE_CHAINED_AFTER,
          {
            matcher: "revert",
            previousMatcher: "revertedWith",
          },
        );
      });

      it("revertedWith: should throw if chained to another non-chainable method", () => {
        assertThrowsHardhatError(
          () =>
            expect(matchers.revertWithCustomErrorWithInt(1))
              .to.be.revertedWithCustomError(matchers, "CustomErrorWithInt")
              .and.to.be.revertedWith("an error message"),
          HardhatError.ERRORS.CHAI_MATCHERS.GENERAL
            .MATCHER_CANNOT_BE_CHAINED_AFTER,
          {
            matcher: "revertedWith",
            previousMatcher: "revertedWithCustomError",
          },
        );
      });

      it("revertedWithCustomError: should throw if chained to another non-chainable method", () => {
        assertThrowsHardhatError(
          () =>
            expect(matchers.revertsWithoutReason())
              .to.be.revertedWithoutReason(ethers)
              .and.to.be.revertedWithCustomError(matchers, "SomeCustomError"),
          HardhatError.ERRORS.CHAI_MATCHERS.GENERAL
            .MATCHER_CANNOT_BE_CHAINED_AFTER,
          {
            matcher: "revertedWithCustomError",
            previousMatcher: "revertedWithoutReason",
          },
        );
      });

      it("revertedWithoutReason: should throw if chained to another non-chainable method", () => {
        assertThrowsHardhatError(
          () =>
            expect(matchers.panicAssert())
              .to.be.revertedWithPanic()
              .and.to.be.revertedWithoutReason(ethers),
          HardhatError.ERRORS.CHAI_MATCHERS.GENERAL
            .MATCHER_CANNOT_BE_CHAINED_AFTER,
          {
            matcher: "revertedWithoutReason",
            previousMatcher: "revertedWithPanic",
          },
        );
      });

      it("revertedWithPanic: should throw if chained to another non-chainable method", async () => {
        const [sender, receiver] = await ethers.getSigners();

        assertThrowsHardhatError(
          () =>
            expect(() =>
              sender.sendTransaction({
                to: receiver,
                value: 200,
              }),
            )
              .to.changeEtherBalance(ethers, sender, "-200")
              .and.to.be.revertedWithPanic(),
          HardhatError.ERRORS.CHAI_MATCHERS.GENERAL
            .MATCHER_CANNOT_BE_CHAINED_AFTER,
          {
            matcher: "revertedWithPanic",
            previousMatcher: "changeEtherBalance",
          },
        );
      });
    });

    describe("with a TxReceipt as its subject", () => {
      it("TxReceipt of a successful transaction", async () => {
        const tx = await mineSuccessfulTransaction(provider, ethers);
        const receipt = await tx.wait();

        await expectAssertionError(
          expect(receipt).to.be.revert(ethers),
          "Expected transaction to be reverted",
        );
        await expect(receipt).to.not.be.revert(ethers);
      });

      it("TxReceipt of a reverted transaction", async () => {
        const tx = await mineRevertedTransaction(provider, ethers, matchers);
        const receipt = await ethers.provider.getTransactionReceipt(tx.hash); // tx.wait rejects, so we use provider.getTransactionReceipt

        await expect(receipt).to.be.revert(ethers);
        await expectAssertionError(
          expect(receipt).to.not.be.revert(ethers),
          "Expected transaction NOT to be reverted",
        );
      });

      it("promise of a TxReceipt of a successful transaction", async () => {
        const tx = await mineSuccessfulTransaction(provider, ethers);
        const receiptPromise = tx.wait();

        await expectAssertionError(
          expect(receiptPromise).to.be.revert(ethers),
          "Expected transaction to be reverted",
        );
        await expect(receiptPromise).to.not.be.revert(ethers);
      });

      it("promise of a TxReceipt of a reverted transaction", async () => {
        const tx = await mineRevertedTransaction(provider, ethers, matchers);
        const receiptPromise = ethers.provider.getTransactionReceipt(tx.hash); // tx.wait rejects, so we use provider.getTransactionReceipt

        await expect(receiptPromise).to.be.revert(ethers);
        await expectAssertionError(
          expect(receiptPromise).to.not.be.revert(ethers),
          "Expected transaction NOT to be reverted",
        );
      });
    });

    describe("calling a contract method that succeeds", () => {
      it("successful asserts", async () => {
        await runSuccessfulAsserts({
          matchers,
          method: "succeeds",
          args: [],
          successfulAssert: (x) => expect(x).to.not.be.revert(ethers),
        });
      });

      it("failed asserts", async () => {
        await runFailedAsserts({
          matchers,
          method: "succeeds",
          args: [],
          failedAssert: (x) => expect(x).to.be.revert(ethers),
          failedAssertReason: "Expected transaction to be reverted",
        });
      });
    });

    describe("calling a method that reverts without a reason", () => {
      it("successful asserts", async () => {
        await runSuccessfulAsserts({
          matchers,
          method: "revertsWithoutReason",
          args: [],
          successfulAssert: (x) => expect(x).to.be.revert(ethers),
        });
      });

      it("failed asserts", async () => {
        await runFailedAsserts({
          matchers,
          method: "revertsWithoutReason",
          args: [],
          failedAssert: (x) => expect(x).not.to.be.revert(ethers),
          failedAssertReason: "Expected transaction NOT to be reverted",
        });
      });
    });

    describe("calling a method that reverts with a reason string", () => {
      it("successful asserts", async () => {
        await runSuccessfulAsserts({
          matchers,
          method: "revertsWith",
          args: ["some reason"],
          successfulAssert: (x) => expect(x).to.be.revert(ethers),
        });
      });

      it("failed asserts", async () => {
        await runFailedAsserts({
          matchers,
          method: "revertsWith",
          args: ["some reason"],
          failedAssert: (x) => expect(x).not.to.be.revert(ethers),
          failedAssertReason:
            "Expected transaction NOT to be reverted, but it reverted with reason 'some reason'",
        });
      });
    });

    describe("calling a method that reverts with a panic code", () => {
      it("successful asserts", async () => {
        await runSuccessfulAsserts({
          matchers,
          method: "panicAssert",
          args: [],
          successfulAssert: (x) => expect(x).to.be.revert(ethers),
        });
      });

      it("failed asserts", async () => {
        await runFailedAsserts({
          matchers,
          method: "panicAssert",
          args: [],
          failedAssert: (x) => expect(x).not.to.be.revert(ethers),
          failedAssertReason:
            "Expected transaction NOT to be reverted, but it reverted with panic code 0x1 (Assertion error)",
        });
      });
    });

    describe("calling a method that reverts with a custom error", () => {
      it("successful asserts", async () => {
        await runSuccessfulAsserts({
          matchers,
          method: "revertWithSomeCustomError",
          args: [],
          successfulAssert: (x) => expect(x).to.be.revert(ethers),
        });
      });

      it("failed asserts", async () => {
        await runFailedAsserts({
          matchers,
          method: "revertWithSomeCustomError",
          args: [],
          failedAssert: (x) => expect(x).not.to.be.revert(ethers),
          failedAssertReason: "Expected transaction NOT to be reverted",
        });
      });
    });

    describe("invalid rejection values", () => {
      it("non-errors", async () => {
        await expectAssertionError(
          expect(Promise.reject({})).to.be.revert(ethers),
          "Expected an Error object",
        );
      });

      it("errors that are not related to a reverted transaction", async () => {
        // use an address that almost surely doesn't have balance
        const randomPrivateKey =
          "0xc5c587cc6e48e9692aee0bf07474118e6d830c11905f7ec7ff32c09c99eba5f9";
        const signer = new ethers.Wallet(randomPrivateKey, ethers.provider);

        // eslint-disable-next-line @typescript-eslint/consistent-type-assertions -- the contract is of type MatchersContract
        const matchersFromSenderWithoutFunds = matchers.connect(
          signer,
        ) as MatchersContract;

        // this transaction will fail because of lack of funds, not because of a
        // revert
        await expect(
          expect(
            matchersFromSenderWithoutFunds.revertsWithoutReason({
              gasLimit: 1_000_000,
            }),
          ).to.not.be.revert(ethers),
        ).to.be.eventually.rejectedWith(
          /^Sender doesn't have enough funds to send tx\. The max upfront cost is: (\d+) and the sender's balance is: (\d+)\.$/,
        );
      });
    });

    describe("stack traces", () => {
      // smoke test for stack traces
      it("includes test file", async () => {
        try {
          await expect(matchers.succeeds()).to.be.revert(ethers);
        } catch (e) {
          const errorString = util.inspect(e);
          expect(errorString).to.include("Expected transaction to be reverted");
          expect(errorString).to.include(
            path.join("test", "matchers", "reverted", "revert.ts"),
          );
          return;
        }
        expect.fail("Expected an exception but none was thrown");
      });
    });
  }
});
